<mujoco>
    <asset>
        <texture type="skybox" builtin="gradient" rgb1="1 1 1" rgb2=".6 .8 1" width="256" height="256"/>
    </asset>
    <worldbody>
        <light diffuse=".5 .5 .5" pos="0 0 3" dir="0 0 -1"/>
        <geom type="plane" size="1 1 0.1" rgba="1 1 1 1"/>
        <body pos="0 0 0.1">
            <joint type="free"/>
            <geom type="box" size=".05 .1 .05" rgba="0 .9 0 1"/>
            <body pos="0 .075 -.05">
                <geom type="cylinder" size="0.0025" fromto="0 0 0 0 0 -.025"/>
                <joint type="hinge" axis="0 0 1"/>
                <body pos="0 0 -.025">
                    <geom type="cylinder" size="0.0025" fromto="-.05 0 0 .05 0 0"/>
                    <body pos=".05 0 0">
                        <joint name="front_right_wheel_joint" type="hinge" axis="1 0 0"/>
                        <geom type="cylinder" size="0.02" fromto="0 0 0 .01 0 0" rgba="0 0 1 1"/>
                    </body>
                    <body pos="-.06 0 0">
                        <joint name="front_left_wheel_joint" type="hinge" axis="1 0 0"/>
                        <geom type="cylinder" size="0.02" fromto="0 0 0 .01 0 0" rgba="1 0 0 1"/>
                    </body>
                </body>
            </body>
            <body pos="0 -.075 -.05">
                <geom type="cylinder" size="0.0025" fromto="0 0 0 0 0 -.025"/>
                <body pos="0 0 -.025">
                    <geom type="cylinder" size="0.0025" fromto="-.05 0 0 .05 0 0"/>
                    <body pos=".05 0 0">
                        <joint name="rear_right_wheel_joint" type="hinge" axis="1 0 0"/>
                        <geom type="cylinder" size="0.02" fromto="0 0 0 .01 0 0" rgba="0 0 1 1"/>
                    </body>
                    <body pos="-.06 0 0">
                        <joint name="rear_left_wheel_joint" type="hinge" axis="1 0 0"/>
                        <geom type="cylinder" size="0.02" fromto="0 0 0 .01 0 0" rgba="1 0 0 1"/>
                    </body>
                </body>
            </body>
        </body>
    </worldbody>
</mujoco>